<?xml version="1.0"?>
<robot name="diff_robot">

    <material name="black">
      <color rgba="0 0 0 1"/>
    </material>

    <material name="white">
      <color rgba="1 1 1 1"/>
    </material>

  <link name="base_link">
    <visual>
      <geometry>
        <box size="0.5 0.5 0.2"/>
      </geometry>
      <material name="white"/>
    </visual>
    <collision>
      <geometry>
        <box size="0.5 0.5 0.2"/>
      </geometry>
    </collision>
    <inertial>
      <mass value="10"/>
      <inertia ixx="0.241" ixy="0.0" ixz="0.0" iyy="0.241" iyz="0.0" izz="0.416"/>
    </inertial>
  </link>

  <link name="front_idler_wheel">
    <visual>
      <geometry>
        <sphere radius="0.025"/>
      </geometry>
      <material name="white"/>
    </visual>
    <collision>
      <geometry>
        <sphere radius="0.025"/>
      </geometry>
    </collision>
    <inertial>
      <mass value="0.10"/>
      <inertia ixx="0.000025" ixy="0.0" ixz="0.0" iyy="0.000025" iyz="0.0" izz="0.000025"/>
    </inertial>
  </link>
  <joint name="front_idler_wheel_joint" type="fixed">
    <parent link="base_link"/>
    <child link="front_idler_wheel"/>
    <origin rpy="0 0 0" xyz="0.2 0.0 -0.1"/>
  </joint>

  <link name="rear_idler_wheel">
    <visual>
      <geometry>
        <sphere radius="0.025"/>
      </geometry>
      <material name="white"/>
    </visual>
    <collision>
      <geometry>
        <sphere radius="0.025"/>
      </geometry>
    </collision>
    <inertial>
      <mass value="0.10"/>
      <inertia ixx="0.000025" ixy="0.0" ixz="0.0" iyy="0.000025" iyz="0.0" izz="0.000025"/>
    </inertial>
  </link>
  <joint name="rear_idler_wheel_joint" type="fixed">
    <parent link="base_link"/>
    <child link="rear_idler_wheel"/>
    <origin rpy="0 0 0" xyz="-0.2 0.0 -0.1"/>
  </joint>

  <link name="right_wheel">
    <visual>
      <origin rpy="1.57075 0 0" xyz="0 0 0"/>
      <geometry>
        <cylinder length="0.1" radius="0.125"/>
      </geometry>
      <material name="black"/>
    </visual>
    <collision>
      <origin rpy="1.57075 0 0" xyz="0 0 0"/>
      <geometry>
        <cylinder length="0.1" radius="0.125"/>
      </geometry>
    </collision>
    <inertial>
      <mass value="1"/>
      <inertia ixx="0.00473" ixy="0.0" ixz="0.0" iyy="0.00781" iyz="0.0" izz="0.00473"/>
    </inertial>
  </link>

  <joint name="right_wheel_joint" type="continuous">
    <axis rpy="0 0 0" xyz="0 1 0"/>
    <parent link="base_link"/>
    <child link="right_wheel"/>
    <origin rpy="0 0 0" xyz="0 -0.3125 0.0"/>
  </joint>

  <!-- This block connects the right_wheel joint to an actuator (motor), which informs both
  simulation and visualization of the robot -->
  <transmission name="right_wheel_trans">
    <type>transmission_interface/SimpleTransmission</type>
    <actuator name="$right_wheel_motor">
      <mechanicalReduction>1</mechanicalReduction>
    </actuator>
    <joint name="right_wheel_joint">
      <hardwareInterface>hardware_interface/VelocityJointInterface</hardwareInterface>
    </joint>
  </transmission>

  <link name="left_wheel">
    <visual>
      <origin rpy="1.57075 0 0" xyz="0 0 0"/>
      <geometry>
        <cylinder length="0.1" radius="0.125"/>
      </geometry>
      <material name="black"/>
    </visual>
    <collision>
      <origin rpy="1.57075 0 0" xyz="0 0 0"/>
      <geometry>
        <cylinder length="0.1" radius="0.125"/>
      </geometry>
    </collision>
    <inertial>
      <mass value="1"/>
      <inertia ixx="0.00473" ixy="0.0" ixz="0.0" iyy="0.00781" iyz="0.0" izz="0.00473"/>
    </inertial>
  </link>

  <joint name="left_wheel_joint" type="continuous">
    <axis rpy="0 0 0" xyz="0 1 0"/>
    <parent link="base_link"/>
    <child link="left_wheel"/>
    <origin rpy="0 0 0" xyz="0 0.3125 0.0"/>
  </joint>
  <!-- This block connects the left_wheel joint to an actuator (motor), which informs both
  simulation and visualization of the robot -->
  <transmission name="left_wheel_trans">
    <type>transmission_interface/SimpleTransmission</type>
    <actuator name="$left_wheel_motor">
      <mechanicalReduction>1</mechanicalReduction>
    </actuator>
    <joint name="left_wheel_joint">
      <hardwareInterface>hardware_interface/VelocityJointInterface</hardwareInterface>
    </joint>
  </transmission>
  <gazebo>
    <plugin name="gazebo_ros_control" filename="libgazebo_ros_control.so">
      <robotNamespace>/</robotNamespace>
      <legacyModeNS>true</legacyModeNS>
    </plugin>
  </gazebo>
  <gazebo reference="base_link">
    <material>Gazebo/Purple</material>
  </gazebo>
  <gazebo reference="right_wheel">
    <mu1 value="200.0"/>
    <mu2 value="100.0"/>
    <kp value="10000000.0" />
    <kd value="1.0" />
    <material>Gazebo/Orange</material>
  </gazebo>
  <gazebo reference="left_wheel">
    <mu1 value="200.0"/>
    <mu2 value="100.0"/>
    <kp value="10000000.0" />
    <kd value="1.0" />
    <material>Gazebo/Orange</material>
  </gazebo>
</robot>
